Workbook

Sheet COVER SHEET
C3: RESERVE BANK OF ZIMBABWE
D4: Licence Number: 000595
C12: RETURN ON CONDITION AND PERFORMANCE OF MICROFINANCE /MONEYLENDING INSTITUTIONS (Form MFI 1)
C16: NOTE:
C17: 1. The return must be signed by the CEO/Managing Director and Chief Accounting Officer
C18: 2. The return is to be prepared in accordance with the instructions provided by the RBZ
C19: 3. The return is due as at the close of business on the last calendar day of the quarter
C20: 4. Reporting is on a cummulative basis for the reporting year, unless specified
C23: NAME OF REPORTING INSTITUTION: | D23: ABC MONEYLENDERS (PRIVATE) LIMITED
C25: DATE OF REPORT: | D25: 42004
C27: We, the undersigned officials:
C29: Name and Signature of Chief Executive Officer/Managing Director | F29: WILLIAM WILEY | I29: ……………………………..
C31: Name and Signature of Chief Accounting Officer | F31: SHYLO KETH | I31: ……………………………..
C33: have reviewed the Return on the Condition and Performance of Microfinance/Moneylending Institution
C34: ﬁled by the named financial institution and certify that the return represents a true and fair representation
C35: of the financial position of the institution.
C38: Name of person to whom questions about this report should be directed
C40: email: byron@abcmoneylenders.co.zw | D40: Telephone: 751904 / 751906
C43: Return form within fourteen (14) days of reporting date to :-
C45: The Senior Division Chief
C46: Bank Licensing, Supervision & Surveillance
C47: Reserve Bank of Zimbabwe
C48: Samora Machel Avenue
C49: HARARE

Sheet COMPREHENSIVE INCOME
A1: STATEMENT OF COMPREHENSIVE INCOME
A3: Institution: | B3: 000595
A4: Financial Year: | B4: 2014
A5: Start Date: | B5: 41583
A6: End Date: | B6: 42004
A8: STATEMENT OF COMPREHENSIVE INCOME (reporting is on a cummulative basis for current year)
C10: CONSOLIDATED
A11: 1 INTEREST INCOME FROM LOANS & ADVANCES (Sum of 1.1 to 1.3) | C11: =SUM(C12:C14) -> 0
A12: 1.1 CONSUMER
A13: 1.2 COMMERCIAL | C13: 0
A14: 1.3 OTHER | C14: 0
A15: 2 INTEREST INCOME AND DISCOUNT RECEIVED FROM INVESTMENTS (Sum of 2.1 to 2.9) | C15: =SUM(C16:C24) -> 0
A16: 2.1 BANK BALANCES | C16: 0
A17: 2.2 TREASURY BILS | C17: 0
A18: 2.3 COMMERCIAL PAPER | C18: 0
A19: 2.4 BANKERS ACCEPTANCES | C19: 0
A20: 2.5 NEGOTIABLE CERTIFICATES OF DEPOSITS | C20: 0
A21: 2.6 GOVERNMENT BONDS | C21: 0
A22: 2.7 LOCAL GOVERNMENT BONDS | C22: 0
A23: 2.8 CORPORATE BONDS | C23: 0
A24: 2.9 OTHER | C24: 0
A25: 3. TOTAL INTEREST INCOME (Sum of 1 and 2) | C25: =C11+C15 -> 0
A26: 4 NON - INTEREST INCOME (Sum of 4.1 to 4.4) | C26: =SUM(C27:C30) -> 0
A27: 4.1 ADMINISTRATION FEES
A28: 4.2 PENALTY FEES | C28: 0
A29: 4.3 INSURANCE INCOME FEES | C29: 0
A30: 4.4 OTHER
A31: 5 TOTAL OPERATING INCOME (Sum of 3 and 4) | C31: =C25+C26 -> 0
A32: 6 INTEREST EXPENSES (Sum of 6.1 to 6.3) | C32: =SUM(C33:C35) -> 0
A33: 6.1 INTEREST AND FEES ON COMMERCIAL DEBT | C33: 0
A34: 6.2 INTEREST ON CONCESSIONAL DEBT | C34: 0
A35: 6.3 INTEREST ON SHAREHOLDERS LOAN
A36: 7 NET INTEREST INCOME (3 minus 6) | C36: =C25-C32 -> 0
A37: 8 PROVISION FOR LOAN LOSSES | C37: =SUM(C38:C39) -> 0
A38: 8.1 SPECIFIC
A39: 8.2 GENERAL
A40: 9 OPERATING EXPENSES (Sum of 9.1 to 9.8) | C40: =SUM(C41:C48) -> 0
A41: 9.1 SALARIES AND EMPLOYEE BENEFITS
A42: 9.2 RENT AND OCCUPATIONAL EXPENSES | C42: 0
A43: 9.3 DIRECTORS FEES | C43: 0
...

Sheet STATEMENT OF FIN POSITION 
A1: ZW-MFI-STATEMENT OF FINANCIAL POSITION
A3: Institution: | B3: ='COMPREHENSIVE INCOME'!B3 -> 000595
A4: Financial Year: | B4: ='COMPREHENSIVE INCOME'!B4 -> 2014
A5: Start Date: | B5: ='COMPREHENSIVE INCOME'!B5 -> 41583
A6: End Date: | B6: ='COMPREHENSIVE INCOME'!B6 -> 42004
A8: BALANCE SHEET
C10: TOTAL AMOUNT ($)
A11: 1 ASSETS
A12: 1.1 CASH AND BANK BALANCES
A13: 1.2 FINANCIAL ASSETS HELD FOR TRADING (SUM of 1.2.1 to 1.2.5) | C13: =SUM(C14:C18) -> 0
A14: 1.2.1 TREASURY BILLS | C14: 0
A15: 1.2.2 NEGOTIABLE CERTIFICATES OF DEPOSITS | C15: 0
A16: 1.2.3 BANKERS ACCEPTANCES | C16: 0
A17: 1.2.4 COMMERCIAL PAPER | C17: 0
A18: 1.2.5 OTHER | C18: 0
A19: 1.3 TOTAL LOANS - Gross (Sum of 1.3.1 to 1.3.3) | C19: =C20+C21+C32 -> 0
A20: 1.3.1 CONSUMER
A21: 1.3.2 COMMERCIAL | C21: =SUM(C22:C31) -> 0
A22: (i) Farming | C22: 0
A23: (ii) Manufacturing | C23: 0
A24: (iii) Mining | C24: 0
A25: (iv) Services | C25: 0
A26: (v) Retail | C26: 0
A27: (vi) Transport | C27: 0
A28: (vii) Health | C28: 0
A29: (viii) Education | C29: 0
A30: (ix) Construction | C30: 0
A31: (x) Distribution
A32: 1.3.3 OTHER | C32: =0 -> 0
A33: 1.3.4 TOTAL PROVISIONS
A34: 1.3.5 NET LOAN PORTFOLIO (1.3 minus 1.3.4) | C34: =C19-C33 -> 0
A35: 1.4 OTHER SHORT-TERM ASSETS
A36: 1.5 TOTAL CURRENT ASSETS (Sum of 1.1.to 1.4) | C36: =C12+C13+C34+C35 -> 0
A37: 1.6 LONG-TERM INVESTMENTS (Sum of 1.6.1 to 1.6.5) | C37: =SUM(C38:C42) -> 0
A38: 1.6.1 GOVERNMENT BONDS | C38: 0
A39: 1.6.2 LOCAL GOVERNMENT BONDS | C39: 0
A40: 1.6.3 CORPORATE BONDS | C40: 0
A41: 1.6.4 PARASTATAL BONDS | C41: 0
A42: 1.6.5 OTHER LONG-TERM INVESTMENTS | C42: 0
A43: 1.7 FIXED ASSETS
...

Sheet SCHEDULE 1 INSIDER LOANS
A1: ZW-MFI-INSIDER-LOANS
A3: Institution: | B3: ='STATEMENT OF FIN POSITION '!B3 -> 000595
A4: Financial Year: | B4: ='STATEMENT OF FIN POSITION '!B4 -> 2014
A5: Start Date: | B5: ='STATEMENT OF FIN POSITION '!B5 -> 41583
A6: End Date: | B6: ='STATEMENT OF FIN POSITION '!B6 -> 42004
A9: SCHEDULE 1 - INSIDER LOANS TO SHAREHOLDERS, DIRECTORS, AND OTHER RELATED PARTIES
A10: Name of Borrower | B10: Relationship to Institution | C10: Total Limit | D10: Amount Outstanding | E10: Interest Rate | F10: Type of Security | G10: Value of Security
A11: TOTAL
A13: N/A

Sheet SCHEDULE 2 LONG TERM DEBT 
A1: ZW-MFI-LONGTERM-DEBT
A3: Institution: | B3: ='SCHEDULE 1 INSIDER LOANS'!B3 -> 000595
A4: Financial Year: | B4: ='SCHEDULE 1 INSIDER LOANS'!B4 -> 2014
A5: Start Date: | B5: ='SCHEDULE 1 INSIDER LOANS'!B5 -> 41583
A6: End Date: | B6: ='SCHEDULE 1 INSIDER LOANS'!B6 -> 42004
A8: SCHEDULE 2 - LONG TERM DEBT
A9: Source of Finance | B9: Amount Borrowed | C9: Outstanding Bal | D9: Interest Rate | E9: Maturity Date
A10: Total

Sheet SCHEDULE 3 ASSET QUALITY
A1: ZW-MFI-ASSET-QUALITY
A3: Institution: | B3: ='SCHEDULE 2 LONG TERM DEBT '!B3 -> 000595
A4: Financial Year: | B4: ='SCHEDULE 2 LONG TERM DEBT '!B4 -> 2014
A5: Start Date: | B5: ='SCHEDULE 2 LONG TERM DEBT '!B5 -> 41583
A6: End Date: | B6: ='SCHEDULE 2 LONG TERM DEBT '!B6 -> 42004
A8: SCHEDULE 3 ASSET QUALITY
A9: CLASSIFICATION OF LOANS
B11: DAYS OUTSTANDING/ARREARS | C11: TOTAL LOANS | D11: SUPERVISORY PROVISION % | E11: PROVISIONS AMOUNT
A12: TOTAL PASS - CURRENT | C12: =SUM(C13:C15) -> 0 | D12: 0.01 | E12: =C12*D12 -> 0
A13: CONSUMER LOANS | B13: 0 | D13: 0.01 | E13: =C13*D13 -> 0
A14: COMMERCIAL LOANS | C14: 0 | D14: 0.01 | E14: =C14*D14 -> 0
A15: OTHER LOANS | C15: 0 | D15: 0.01 | E15: =C15*D15 -> 0
A16: TOTAL SPECIAL MENTION | B16: 1 - 30 DAYS | C16: =SUM(C17:C19) -> 0 | D16: 0.2 | E16: =C16*D16 -> 0
A17: CONSUMER LOANS | D17: 0.2 | E17: =C17*D17 -> 0
A18: COMMERCIAL LOANS | C18: 0 | D18: 0.2 | E18: =C18*D18 -> 0
A19: OTHER LOANS | C19: 0 | D19: 0.2 | E19: =C19*D19 -> 0
A20: TOTAL SUBSTANDARD | B20: 31 - 60 DAYS | C20: =SUM(C21:C23) -> 0 | D20: 0.5 | E20: =C20*D20 -> 0
A21: CONSUMER LOANS | C21: 0 | D21: 0.5 | E21: =C21*D21 -> 0
A22: COMMERCIAL LOANS | C22: 0 | D22: 0.5 | E22: =C22*D22 -> 0
A23: OTHER LOANS | C23: 0 | D23: 0.5 | E23: =C23*D23 -> 0
A24: TOTAL DOUBTFUL | B24: 61 - 90 DAYS | C24: =SUM(C25:C27) -> 0 | D24: 0.75 | E24: =C24*D24 -> 0
A25: CONSUMER LOANS | D25: 0.75 | E25: =C25*D25 -> 0
A26: COMMERCIAL LOANS | C26: 0 | D26: 0.75 | E26: =C26*D26 -> 0
A27: OTHER LOANS | C27: 0 | D27: 0.75 | E27: =C27*D27 -> 0
A28: TOTAL LOSS | B28: +91 DAYS | C28: =SUM(C29:C31) -> 0 | D28: 1 | E28: =C28*D28 -> 0
A29: CONSUMER LOANS | D29: 1 | E29: =C29*D29 -> 0
A30: COMMERCIAL LOANS | C30: 0 | D30: 1 | E30: =C30*D30 -> 0
A31: OTHER LOANS | C31: 0 | D31: 1 | E31: =C31*D31 -> 0
A32: GRAND TOTAL | C32: =C12+C16+C20+C24+C28 -> 0 | E32: =E12+E16+E20+E24+E28 -> 0
A33: SPECIFIC PROVISIONS | E33: =E20+E24+E28 -> 0
A34: GENERAL PROVISIONS | E34: =E12+E16 -> 0

Sheet SCHEDULE 4 DISTRIBUTION 
A1: ZW-MFI-DISTRIBUTION OF LOANS AND ADVANCES
A3: Institution: | B3: ='SCHEDULE 3 ASSET QUALITY'!B3 -> 000595
A4: Financial Year: | B4: ='SCHEDULE 3 ASSET QUALITY'!B4 -> 2014
A5: Start Date: | B5: ='SCHEDULE 3 ASSET QUALITY'!B5 -> 41583
A6: End Date: | B6: ='SCHEDULE 3 ASSET QUALITY'!B6 -> 42004
A8: SCHEDULE 4 - DISTRIBUTION OF LOANS & ADVANCES
A9: PURPOSE OF LOAN | B9: NUMBER OF CLIENTS | C9: NUMBER OF LOANS | D9: VALUE | E9: PERCENTAL OF TOTAL LOANS
A10: TOTAL | B10: =SUM(B11:B23) -> 0 | C10: =SUM(C11:C23) -> 0 | D10: =SUM(D11:D23) -> 0 | E10: =D10/D10 -> #DIV/0!
A11: DISTRIBUTION | B11: 0 | E11: =D11/$D$10 -> #DIV/0!
A12: MANUFACTURING | E12: =D12/$D$10 -> #DIV/0!
A13: RETAIL | E13: =D13/$D$10 -> #DIV/0!
A14: CONSUMPTION | E14: =D14/$D$10 -> #DIV/0!
A15: SERVICES | E15: =D15/$D$10 -> #DIV/0!
A16: HEALTH | E16: =D16/$D$10 -> #DIV/0!
A17: EDUCATION | E17: =D17/$D$10 -> #DIV/0!
A18: MINING | E18: =D18/$D$10 -> #DIV/0!
A19: AGRICULTURE | E19: =D19/$D$10 -> #DIV/0!
A20: CROSS BORDER TRADERS | E20: =D20/$D$10 -> #DIV/0!
A21: VENDORS | E21: =D21/$D$10 -> #DIV/0!
A22: FUNERAL ASSISTANCE | E22: =D22/$D$10 -> #DIV/0!
A23: OTHER | E23: =D23/$D$10 -> #DIV/0!

Sheet SCHEDULE 5 GENDER DISTRIBUTION 
A1: ZW-MFI-DISTRIBUTION OF LOANS AND ADVANCES
A3: Institution: | B3: ='SCHEDULE 4 DISTRIBUTION '!B3 -> 000595
A4: Financial Year: | B4: ='SCHEDULE 4 DISTRIBUTION '!B4 -> 2014
A5: Start Date: | B5: ='SCHEDULE 4 DISTRIBUTION '!B5 -> 41583
A6: End Date: | B6: ='SCHEDULE 4 DISTRIBUTION '!B6 -> 42004
A8: SCHEDULE 5 - DISTRIBUTION OF LOANS & ADVANCES
A9: PURPOSE OF LOAN | B9: NUMBER OF FEMALE CLIENTS | C9: TOTAL NUMBER OF LOANS | D9: VALUE | E9: PERCENTAL OF TOTAL LOANS
A10: TOTAL | B10: =SUM(B11:B23) -> 0 | C10: =SUM(C11:C23) -> 0 | D10: =SUM(D11:D23) -> 0 | E10: =D10/D10 -> #DIV/0!
A11: DISTRIBUTION | E11: =D11/$D$10 -> #DIV/0!
A12: MANUFACTURING | E12: =D12/$D$10 -> #DIV/0!
A13: RETAIL | E13: =D13/$D$10 -> #DIV/0!
A14: CONSUMPTION | E14: =D14/$D$10 -> #DIV/0!
A15: SERVICES | E15: =D15/$D$10 -> #DIV/0!
A16: HEALTH | E16: =D16/$D$10 -> #DIV/0!
A17: EDUCATION | E17: =D17/$D$10 -> #DIV/0!
A18: MINING | E18: =D18/$D$10 -> #DIV/0!
A19: AGRICULTURE | E19: =D19/$D$10 -> #DIV/0!
A20: CROSS BORDER TRADERS | E20: =D20/$D$10 -> #DIV/0!
A21: VENORS | E21: =D21/$D$10 -> #DIV/0!
A22: FUNERAL ASSISTANCE | E22: =D22/$D$10 -> #DIV/0!
A23: OTHER | E23: =D23/$D$10 -> #DIV/0!

Sheet SCHEDULE 6 MATURITY PROF
A1: ZW-MFI-MATURITY-PROFILE
A3: Institution: | B3: ='SCHEDULE 5 GENDER DISTRIBUTION '!B3 -> 000595
A4: Financial Year: | B4: ='SCHEDULE 5 GENDER DISTRIBUTION '!B4 -> 2014
A5: Start Date: | B5: ='SCHEDULE 5 GENDER DISTRIBUTION '!B5 -> 41583
A6: End Date: | B6: ='SCHEDULE 5 GENDER DISTRIBUTION '!B6 -> 42004
A8: SCHEDULE 6 - MATURITY PROFILE (Asset & Liability Maturities)
B10: CASH INFLOWS | C10: CASH OUTFLOWS (Maturing Liabilities) | D10: Net Position | E10: Cumulative Position
A11: TOTAL INFLOWS / OUTFLOWS | B11: =SUM(B12:B19) -> 0 | C11: =SUM(C12:C19) -> 0 | D11: =B11-C11 -> 0 | E11: =D11 -> 0
A12: i) 0 -7 days | D12: =B12-C12 -> 0 | E12: =D12 -> 0
A13: ii) 8 - 14 days | D13: =B13-C13 -> 0 | E13: =E12+D13 -> 0
A14: iii) 15 - 30 days | D14: =B14-C14 -> 0 | E14: =E13+D14 -> 0
A15: iv) 31 - 60 days | D15: =B15-C15 -> 0 | E15: =E14+D15 -> 0
A16: v) 61 - 90 days | D16: =B16-C16 -> 0 | E16: =E15+D16 -> 0
A17: vi) 91 - 120 days | D17: =B17-C17 -> 0 | E17: =E16+D17 -> 0
A18: vii) 121 - 180 days | B18: 0 | C18: 0 | D18: =B18-C18 -> 0 | E18: =E17+D18 -> 0
A19: viii) 181 - 360 days | B19: 0 | C19: 0 | D19: =B19-C19 -> 0 | E19: =E18+D19 -> 0
A21: 0-7
A22: ii) 8 - 14 days
A23: iii) 15 - 30 days
A24: iv) 31 - 60 days
A25: v) 61 - 90 days
A26: vi) 91 - 120 days
A27: vii) 121 - 180 days
A28: viii) 181 - 360 days

Sheet SCHEDULE 7 TOP 20 BORROW  
A1: ZW-MFI-TOP-20-BORROWERS
A3: Institution: | B3: ='SCHEDULE 6 MATURITY PROF'!B3 -> 000595
A4: Financial Year: | B4: ='SCHEDULE 6 MATURITY PROF'!B4 -> 2014
A5: Start Date: | B5: ='SCHEDULE 6 MATURITY PROF'!B5 -> 41583
A6: End Date: | B6: ='SCHEDULE 6 MATURITY PROF'!B6 -> 42004
A8: SCHEDULE 7 - TOP TWENTY BORROWERS
A9: NAME OF BORROWER | B9: TOTAL AMOUNT BORROWED | C9: BALANCE OUTSTANDING | D9: MATURITY DATE | E9: TYPE OF SECURITY | F9: VALUE OF SECURITY
A10: TOTAL

Sheet SCHEDULE 8
A1: ZW-MFI-PORTFOLIO-MGMT
A3: Institution: | B3: 000595
A4: ZW-MFI-PORTFOLIO-MGMT
A6: Institution: | B6: 000595
A7: Financial Year: | B7: ='SCHEDULE 7 TOP 20 BORROW '!B4 -> 2014
A8: Start Date: | B8: ='SCHEDULE 7 TOP 20 BORROW '!B5 -> 41583
A9: End Date: | B9: ='SCHEDULE 7 TOP 20 BORROW '!B6 -> 42004
A11: SCHEDULE 8 - PORTFOLIO MANAGEMENT
A13: 1 PORTFOLIO ACTIVITY | C13: VALUE / NUMBER
A14: 1.1 NUMBER OF LOANS DISBURSED
A15: 1.2 VALUE OF LOANS DISBURSED
A16: 1.3 NUMBER OF CLIENTS TAKING FIRST LOAN
A17: 1.4 NUMBER OF CLIENTS TAKING SECOND AND SUBSEQUENT LOANS
A18: 1.5 NUMBER OF ACTIVE CLIENTS AT START OF QUARTER
A19: 1.6 NUMBER OF ACTIVE CLIENTS AT END OF QUARTER
A20: 1.7 DROP OUR / GROWTH RATE (%) | C20: =(C19-C18)/C18 -> #DIV/0!
A21: 1.8 NUMBER OF OUTSTANDNG LOANS
A22: 1.9 AVERAGE LOAN TERM IN MONTHS
A23: 1.10 TOTAL NUMBER OF ALL CLIENTS (ACTIVE + NON ACTIVE)
A24: 2 OUTREACH
A25: 2.1 NUMBER OF BRANCHES
A26: 2.1.1 URBAN
A27: 2.1.2 RURAL
A28: 2.2 NUMBER OF ACTIVE LOAN CLIENTS IN RURAL BRANCHES (definition)
A29: 2.3 NUMBER OF BORROWING GROUPS
A30: 2.4 NUMBER OF ACTIVE LOAN CLIENTS RECEIVING LOANS AS MEMBERS OF A GROUP
A31: 2.5 NUMBER OF ACTIVE LOAN CLIENTS RECEIVING LOANS AS INDIVIDUALS
A32: 2.6 NUMBER OF LOANS WITH A DISBURSED LOAN AMOUNT MORE THAN $5,000
... A44: 3.10 SCHEDULED AMOUNTS DUE IN PERIOD PLUS ARREARS
A45: 3.11 COLLECTION RATE (%) | B45: =C43/C44 -> #DIV/0!
A46: 3.12 VALUE OF ROLLED OVER / RENEGOTIATED LOANS | C46: 0
A47: 3.13 NUMBER OF ROLLED OVER / RENEGOTIATED LOANS | C47: 0
A48: 4. WRITE-OFFS
A49: 4.1 NUMBER OF LOANS WRITTEN OFF DURING PERIOD
A50: 4.2 VALUE OF LOANS WRITTEN OFF
A51: 4.3 NUMBER OF LOANS UNDER LITIGATION
A52: 4.4 VALUE OF LOANS UNDER LITIGATION

Sheet SCHEDULE 9 CO. PROFILE 
A1: ZW-MFI-PROFILE
A3: Institution: | B3: ='SCHEDULE 8'!B6 -> 000595
A4: Financial Year: | B4: ='SCHEDULE 8'!B7 -> 2014
A5: Start Date: | B5: ='SCHEDULE 8'!B8 -> 41583
A6: End Date: | B6: ='SCHEDULE 8'!B9 -> 42004
A8: SCHEDULE 9 - COMPANY PROFILE
A9: 1 NAME OF INSTITUTION | B9: ABC MONEYLENDERS (PRIVATE) LIMITED
A10: 2 LICENCE NUMBER | B10: 000595
A11: 3 DATE COMMENCED OPERATIONS | B11: ='COMPREHENSIVE INCOME'!B5 -> 41583
A12: 4 PHYSICAL ADDRESS | B12: HATFIELD HOUSE, SEKE RD, GRANITESIDE, HARARE
A13: 5 POSTAL ADDRESS | B13: PO BOX 1407, HARARE
A14: 6 CONTACT TELEPHONES | B14: 751904 / 751906
A15: 7 CONTACT PERSON | B15: BYRON WILEY
A16: 8 NUMBER OF BRANCHES | B16: ='SCHEDULE 8'!C25 -> 0
A17: 9 NUMBER OF EMPLOYEES | B17: =B18+B19 -> 2
A18: 9 (a) Females | B18: 1
A19: 9 (b) Male | B19: 1
A20: 10 NUMBER OF LOAN OFFICERS | B20: 1
A21: 10 (a) Female | B21: 0
A22: 10 (b) Male | B22: 1
A23: 11 EXTERNAL AUDITORS | B23: N/A
A24: 12 BANKERS | B24: BARCLAYS BANK
A25: 13 LAWYERS | B25: WINTERTONS
